Workbook

Sheet DASE DADOS - DISTANCIA
A1: CLIFFOR | B1: PRODUTOR | C1: AVIÁRIO | D1: PRODUTOR TESTE | E1: MUNICÍPIO | F1: KM | G1: DISTÂNCIA | H1: COORDENADAS | I1: EMPRESA | J1: KM PARA PAGAMENTO DOS FRETES
A2: 111058 | B2: ABEL ANGELO DA COSTA CONCEICAO | C2: A1 | D2: ABEL ANGELO DA COSTA CONCEICAO A1 | E2: CASCAVEL | F2: 54 | G2: 27 | H2: -25.074721958480097, -53.40203649347913 | I2: PLUMA | J2: 54
A3: 29890 | B3: IVANIR GIRELLI | C3: A1 | D3: IVANIR GIRELLI A1 | E3: SANTO ANTÔNIO DO SUDOESTE | F3: 331 | G3: 178 | H3: -26.055538226278127, -53.6066631357838 | I3: PLUSVAL | J3: 331
A4: 5365040 | B4: ADAIR JOSE DELAMURA | C4: A1 | D4: ADAIR JOSE DELAMURA A1 | E4: TUPASSI | F4: 106 | G4: 60 | H4: -24.621722060057024, -53.471299863665145 | I4: PLUMA | J4: 106
A5: 29890 | B5: IVANIR GIRELLI | C5: A2 | D5: IVANIR GIRELLI A2 | E5: SANTO ANTÔNIO DO SUDOESTE | F5: 331 | G5: 178 | H5: -26.055174366832272, -53.60674597310789 | I5: PLUSVAL | J5: 331
A6: 30448 | B6: ADAO RICARDO DOS SANTOS | C6: A1 | D6: ADAO RICARDO DOS SANTOS A1 | E6: TRÊS BARRAS DO PARANÁ | F6: 226 | G6: 120 | H6: -25.533910195126577, -53.253383608219075 | I6: PLUSVAL | J6: 226
A7: 29909 | B7: MOACIR JOSE MORASKI | C7: A3 | D7: MOACIR JOSE MORASKI A3 | E7: PRANCHITA | F7: 276 | G7: 159 | H7: -25.92823759413807, -53.69998684562199 | I7: PLUSVAL | J7: 276
A8: 30064 | B8: ADELAR GEBAUER | C8: A2 | D8: ADELAR GEBAUER A2 | E8: CAPANEMA | F8: 260 | G8: 131 | H8: -25.593268645824793, -53.94207083135666 | I8: PLUSVAL | J8: 260
A9: 30668 | B9: IARA MARIA SIGNOR LAZAROTO | C9: A1 | D9: IARA MARIA SIGNOR LAZAROTO A1 | E9: SANTO ANTÔNIO DO SUDOESTE | F9: 336 | G9: 179 | H9: -26.039811028436684, -53.574678615911814 | I9: PLUSVAL | J9: 336
A10: 30064 | B10: ADELAR GEBAUER | C10: A1 | D10: ADELAR GEBAUER A1 | E10: CAPANEMA | F10: 260 | G10: 131 | H10: -25.59318530178808, -53.941644050123806 | I10: PLUSVAL | J10: 260
A11: 30668 | B11: IARA MARIA SIGNOR LAZAROTO | C11: A2 | D11: IARA MARIA SIGNOR LAZAROTO A2 | E11: SANTO ANTÔNIO DO SUDOESTE | F11: 336 | G11: 179 | H11: -26.039668902296437, -53.57499849568053 | I11: PLUSVAL | J11: 336
A12: 5760739 | B12: ADELAR LUIZ STURMER | C12: A1 | D12: ADELAR LUIZ STURMER A1 | E12: CASCAVEL | F12: 68 | G12: 34 | H12: -25.136017091410526, -53.337952095655254 | I12: PLUMA | J12: 68
A13: 30668 | B13: IARA MARIA SIGNOR LAZAROTO | C13: A3 | D13: IARA MARIA SIGNOR LAZAROTO A3 | E13: SANTO ANTÔNIO DO SUDOESTE | F13: 336 | G13: 179 | H13: -26.039421760964533, -53.574761886273365 | I13: PLUSVAL | J13: 336
... A33: 44305 | B33: ODIVAL PEREIRA | C33: A1 | D33: ODIVAL PEREIRA A1 | E33: SANTO ANTÔNIO DO SUDOESTE | F33: 336 | G33: 184 | H33: -26.070705337223526, -53.57487829842561 | I33: PLUSVAL | J33: 336
B34: ADRIANA DIEDRICHS | C34: A4 | D34: ADRIANA DIEDRICHS A4 | E34: TOLEDO | F34: 155 | G34: 78 | H34: -24.571808297265253, -53.80042513015339 | I34: PLUMA | J34: 155
A35: 29436 | B35: ALEXANDRE DAVI MARAN | C35: A1 | D35: ALEXANDRE DAVI MARAN A1 | E35: SANTO ANTÔNIO DO SUDOESTE | F35: 333 | G35: 183 | H35: -26.06451486476763, -53.60680502528411 | I35: PLUSVAL | J35: 333
B36: ADRIANA DIEDRICHS | C36: A3 | D36: ADRIANA DIEDRICHS A3 | E36: TOLEDO | F36: 155 | G36: 78 | H36: -24.571808297265253, -53.80042513015339 | I36: PLUMA | J36: 155
A37: 29910 | B37: PAULO RODRIGUES DOS SANTOS | C37: A1 | D37: PAULO RODRIGUES DOS SANTOS A1 | E37: PRANCHITA | F37: 323 | G37: 166 | H37: -25.964879803095187, -53.61283319118804 | I37: PLUSVAL | J37: 323
A38: 1123572 | B38: ADRIANO AHMANN | C38: A1 | D38: ADRIANO AHMANN A1 | E38: CAPANEMA | F38: 260 | G38: 130 | H38: -25.594807671063716, -53.92156907664948 | I38: PLUSVAL | J38: 260
A39: 30060 | B39: ELTON HOFF | C39: A1 | D39: ELTON HOFF A1 | E39: SANTO ANTÔNIO DO SUDOESTE | F39: 338 | G39: 184 | H39: -26.06882912019864, -53.564553403097115 | I39: PLUSVAL | J39: 338
A40: 58390 | B40: ADRIANO LAZZAROTO | C40: A1 | D40: ADRIANO LAZZAROTO A1 | E40: SANTO ANTÔNIO DO SUDOESTE | F40: 338 | G40: 166 | H40: -26.10612896666298, -53.69777271419382 | I40: PLUSVAL | J40: 338
A41: 30478 | B41: TANIA MARIA TOFFOLI BALESTRIN | C41: A1 | D41: TANIA MARIA TOFFOLI BALESTRIN A1 | E41: SANTO ANTÔNIO DO SUDOESTE | F41: 325 | G41: 172 | H41: -26.023494493050134, -53.627973778965696 | I41: PLUSVAL | J41: 325
A42: 4390792 | B42: ADRIANO LUCAS BRIXNER | C42: A2 | D42: ADRIANO LUCAS BRIXNER A2 | E42: TUPASSI | F42: 126 | G42: 63 | H42: -24.5610192645159, -53.50315900044176 | I42: PLUMA | J42: 126
A43: 30478 | B43: TANIA MARIA TOFFOLI BALESTRIN | C43: A2 | D43: TANIA MARIA TOFFOLI BALESTRIN A2 | E43: SANTO ANTÔNIO DO SUDOESTE | F43: 325 | G43: 172 | H43: -26.023938327883517, -53.6278658593625 | I43: PLUSVAL | J43: 325
A44: 4390792 | B44: ADRIANO LUCAS BRIXNER | C44: A1 | D44: ADRIANO LUCAS BRIXNER A1 | E44: TUPASSI | F44: 126 | G44: 63 | H44: -24.5610192645159, -53.50315900044176 | I44: PLUMA | J44: 126
A45: 1147641 | B45: CLAUDECIR ROBERTI | C45: A2 | D45: CLAUDECIR ROBERTI A2 | E45: SANTO ANTÔNIO DO SUDOESTE | F45: 321 | G45: 170 | H45: -26.03219041572988, -53.66183201156584 | I45: PLUSVAL | J45: 321
A46: 30047 | B46: ADRIANO ROBERTO FUHR DREY | C46: A1 | D46: ADRIANO ROBERTO FUHR DREY A1 | E46: PLANALTO | F46: 260 | G46: 130 | H46: -25.71447627307871, -53.7390284849861 | I46: PLUSVAL | J46: 260
A47: 1147641 | B47: CLAUDECIR ROBERTI | C47: A3 | D47: CLAUDECIR ROBERTI A3 | E47: SANTO ANTÔNIO DO SUDOESTE | F47: 321 | G47: 170 | H47: -26.031443923633542, -53.662295067079015 | I47: PLUSVAL | J47: 321
A48: 29421 | B48: ADRIANO CESAR BILIBIO | C48: A1 | D48: ADRIANO CESAR BILIBIO A1 | E48: CAPITÃO LEÔNIDAS MARQUES | F48: 138 | G48: 72 | H48: -25.49322778288772, -53.59177741995077 | I48: PLUSVAL | J48: 138
... A59: 29905 | B59: MARCO AURELIO TEOLOGIDES MARCON | C59: A1 | D59: MARCO AURELIO TEOLOGIDES MARCON A1 | E59: PRANCHITA | F59: 312 | G59: 156 | H59: -25.964207998728106, -53.68696912224942 | I59: PLUSVAL | J59: 312
B60: ALBANY JESSE SCHAIDT | C60: A1 | D60: ALBANY JESSE SCHAIDT A1 | E60: LINDOESTE | F60: 72 | G60: 36 | H60: -25.191553411002136, -53.574568685964294 | I60: PLUMA | J60: 72
A61: 29905 | B61: MARCO AURELIO TEOLOGIDES MARCON | C61: A2 | D61: MARCO AURELIO TEOLOGIDES MARCON A2 | E61: PRANCHITA | F61: 312 | G61: 156 | H61: -25.964302150062316, -53.68736623909972 | I61: PLUSVAL | J61: 312
B62: ALBANY JESSE SCHAIDT | C62: A2 | D62: ALBANY JESSE SCHAIDT A2 | E62: LINDOESTE | F62: 72 | G62: 36 | H62: -25.191553411002136, -53.574568685964294 | I62: PLUMA | J62: 72
A63: 29905 | B63: MARCO AURELIO TEOLOGIDES MARCON | C63: A3 | D63: MARCO AURELIO TEOLOGIDES MARCON A3 | E63: PRANCHITA | F63: 312 | G63: 156 | H63: -25.964432630102436, -53.68760052309158 | I63: PLUSVAL | J63: 312
A64: 5335906 | B64: ALCIDES BRAGAGNOLLO | C64: A1 | D64: ALCIDES BRAGAGNOLLO A1 | E64: TOLEDO | F64: 151 | G64: 76 | H64: -24.574109727129024, -53.80988713797703 | I64: PLUMA | J64: 151
A65: 29905 | B65: MARCO AURELIO TEOLOGIDES MARCON | C65: A4 | D65: MARCO AURELIO TEOLOGIDES MARCON A4 | E65: PRANCHITA | F65: 312 | G65: 156 | H65: -25.964432630102436, -53.68760052309158 | I65: PLUSVAL | J65: 312
A66: 29953 | B66: EDER THEODORO | C66: A2 | D66: EDER THEODORO A2 | E66: PLANALTO | F66: 237 | G66: 133 | H66: -25.69219055737269, -53.73129892089923 | I66: PLUSVAL | J66: 237
A67: 5393000 | B67: ALTAMIR GOMES | C67: A2 | D67: ALTAMIR GOMES A2 | E67: CASCAVEL | F67: 39 | G67: 20 | H67: -24.91526095888856, -53.361577464670766 | I67: PLUMA | J67: 39
A68: 30621 | B68: CLEIDSON ALBERTO PILATTI | C68: A2 | D68: CLEIDSON ALBERTO PILATTI A2 | E68: PÉROLA DO OESTE | F68: 282 | G68: 143 | H68: -25.92536638415823, -53.748992089128315 | I68: PLUSVAL | J68: 282
A69: 5393000 | B69: ALTAMIR GOMES | C69: A1 | D69: ALTAMIR GOMES A1 | E69: CASCAVEL | F69: 39 | G69: 20 | H69: -24.91526095888856, -53.361577464670766 | I69: PLUMA | J69: 39
...

Sheet Tabela 1
A1: Tipo de carga | B1: CCD (R$/km) | C1: CC (R$ fixo)
A2: Granel sólido | B2: 4.578 | C2: 194.44

Sheet CALCULO CTE
A1: CLIFFOR | B1: ENIR | C1: SO | D1: MUNICÍPIO | E1: EMPRESA | F1: KM distancia | G1: KM PARA PAGAMENTO DOS FRETES | H1: R$ Mín | I1: Valor1 | J1: R$/KM | K1: Valor CC | L1: Valor CCD | M1: Valor CTE
A2: ='DASE DADOS - DISTANCIA'!A2 -> 111058 | C2: ='DASE DADOS - DISTANCIA'!C2 -> A1 | D2: ='DASE DADOS - DISTANCIA'!E2 -> CASCAVEL | E2: ='DASE DADOS - DISTANCIA'!I2 -> PLUMA | F2: 27 | G2: ='DASE DADOS - DISTANCIA'!J2 -> 54 | H2: 420 | I2: =IF(#REF!<17200,DISTÂNCIA3[[#This Row],[KM PARA PAGAMENTO DOS FRETES]]*4.74,((#REF!/17200)*4.74)*DISTÂNCIA3[[#This Row],[KM PARA PAGAMENTO DOS FRETES]]) -> #REF! | J2: =DISTÂNCIA3[[#This Row],[Valor CTE]]/DISTÂNCIA3[[#This Row],[KM PARA PAGAMENTO DOS FRETES]] -> 7.9955556 | K2: =ROUND((F2*4.578)+194.44,2) -> 318.05 | L2: =0.92*DISTÂNCIA3[[#This Row],[KM distancia]]*4.578 -> 113.71752 | M2: =ROUND(((F2*4.578)+194.44)+(0.92*F2*4.578),2) -> 431.76
A3: ='DASE DADOS - DISTANCIA'!A3 -> 29890 | B3: ='DASE DADOS - DISTANCIA'!B3 -> IVANIR GIRELLI | C3: ='DASE DADOS - DISTANCIA'!C3 -> A1 | D3: ='DASE DADOS - DISTANCIA'!E3 -> SANTO ANTÔNIO DO SUDOESTE | E3: ='DASE DADOS - DISTANCIA'!I3 -> PLUSVAL | F3: 166 | G3: ='DASE DADOS - DISTANCIA'!J3 -> 331 | H3: 420 | I3: =IF(#REF!<17200,DISTÂNCIA3[[#This Row],[KM PARA PAGAMENTO DOS FRETES]]*4.74,((#REF!/17200)*4.74)*DISTÂNCIA3[[#This Row],[KM PARA PAGAMENTO DOS FRETES]]) -> #REF! | J3: =DISTÂNCIA3[[#This Row],[Valor CTE]]/DISTÂNCIA3[[#This Row],[KM PARA PAGAMENTO DOS FRETES]] -> 4.9955891 | K3: =ROUND((F3*4.578)+194.44,2) -> 954.39 | L3: =0.92*DISTÂNCIA3[[#This Row],[KM distancia]]*4.578 -> 699.15216 | M3: =ROUND(((F3*4.578)+194.44)+(0.92*F3*4.578),2) -> 1653.54
A4: ='DASE DADOS - DISTANCIA'!A4 -> 5365040 | B4: ='DASE DADOS - DISTANCIA'!B4 -> ADAIR JOSE DELAMURA | C4: ='DASE DADOS - DISTANCIA'!C4 -> A1 | D4: ='DASE DADOS - DISTANCIA'!E4 -> TUPASSI | E4: ='DASE DADOS - DISTANCIA'!I4 -> PLUMA | F4: 53 | G4: ='DASE DADOS - DISTANCIA'!J4 -> 106 | H4: 420 | I4: =IF(#REF!<17200,DISTÂNCIA3[[#This Row],[KM PARA PAGAMENTO DOS FRETES]]*4.74,((#REF!/17200)*4.74)*DISTÂNCIA3[[#This Row],[KM PARA PAGAMENTO DOS FRETES]]) -> #REF! | J4: =DISTÂNCIA3[[#This Row],[Valor CTE]]/DISTÂNCIA3[[#This Row],[KM PARA PAGAMENTO DOS FRETES]] -> 6.2292453 | K4: =ROUND((F4*4.578)+194.44,2) -> 437.07 | L4: =0.92*DISTÂNCIA3[[#This Row],[KM distancia]]*4.578 -> 223.22328 | M4: =ROUND(((F4*4.578)+194.44)+(0.92*F4*4.578),2) -> 660.3
A5: ='DASE DADOS - DISTANCIA'!A5 -> 29890 | B5: ='DASE DADOS - DISTANCIA'!B5 -> IVANIR GIRELLI | C5: ='DASE DADOS - DISTANCIA'!C5 -> A2 | D5: ='DASE DADOS - DISTANCIA'!E5 -> SANTO ANTÔNIO DO SUDOESTE | E5: ='DASE DADOS - DISTANCIA'!I5 -> PLUSVAL | F5: 166 | G5: ='DASE DADOS - DISTANCIA'!J5 -> 331 | H5: 420 | I5: =IF(#REF!<17200,DISTÂNCIA3[[#This Row],[KM PARA PAGAMENTO DOS FRETES]]*4.74,((#REF!/17200)*4.74)*DISTÂNCIA3[[#This Row],[KM PARA PAGAMENTO DOS FRETES]]) -> #REF! | J5: =DISTÂNCIA3[[#This Row],[Valor CTE]]/DISTÂNCIA3[[#This Row],[KM PARA PAGAMENTO DOS FRETES]] -> 4.9955891 | K5: =ROUND((F5*4.578)+194.44,2) -> 954.39 | L5: =0.92*DISTÂNCIA3[[#This Row],[KM distancia]]*4.578 -> 699.15216 | M5: =ROUND(((F5*4.578)+194.44)+(0.92*F5*4.578),2) -> 1653.54
A6: ='DASE DADOS - DISTANCIA'!A6 -> 30448 | B6: ='DASE DADOS - DISTANCIA'!B6 -> ADAO RICARDO DOS SANTOS | C6: ='DASE DADOS - DISTANCIA'!C6 -> A1 | D6: ='DASE DADOS - DISTANCIA'!E6 -> TRÊS BARRAS DO PARANÁ | E6: ='DASE DADOS - DISTANCIA'!I6 -> PLUSVAL | F6: 113 | G6: ='DASE DADOS - DISTANCIA'!J6 -> 226 | H6: 420 | I6: =IF(#REF!<17200,DISTÂNCIA3[[#This Row],[KM PARA PAGAMENTO DOS FRETES]]*4.74,((#REF!/17200)*4.74)*DISTÂNCIA3[[#This Row],[KM PARA PAGAMENTO DOS FRETES]]) -> #REF! | J6: =DISTÂNCIA3[[#This Row],[Valor CTE]]/DISTÂNCIA3[[#This Row],[KM PARA PAGAMENTO DOS FRETES]] -> 5.2552212 | K6: =ROUND((F6*4.578)+194.44,2) -> 711.75 | L6: =0.92*DISTÂNCIA3[[#This Row],[KM distancia]]*4.578 -> 475.92888 | M6: =ROUND(((F6*4.578)+194.44)+(0.92*F6*4.578),2) -> 1187.68
A7: ='DASE DADOS - DISTANCIA'!A7 -> 29909 | B7: ='DASE DADOS - DISTANCIA'!B7 -> MOACIR JOSE MORASKI | C7: ='DASE DADOS - DISTANCIA'!C7 -> A3 | D7: ='DASE DADOS - DISTANCIA'!E7 -> PRANCHITA | E7: ='DASE DADOS - DISTANCIA'!I7 -> PLUSVAL | F7: 138 | G7: ='DASE DADOS - DISTANCIA'!J7 -> 276 | H7: 420 | I7: =IF(#REF!<17200,DISTÂNCIA3[[#This Row],[KM PARA PAGAMENTO DOS FRETES]]*4.74,((#REF!/17200)*4.74)*DISTÂNCIA3[[#This Row],[KM PARA PAGAMENTO DOS FRETES]]) -> #REF! | J7: =DISTÂNCIA3[[#This Row],[Valor CTE]]/DISTÂNCIA3[[#This Row],[KM PARA PAGAMENTO DOS FRETES]] -> 5.0993841 | K7: =ROUND((F7*4.578)+194.44,2) -> 826.2 | L7: =0.92*DISTÂNCIA3[[#This Row],[KM distancia]]*4.578 -> 581.22288 | M7: =ROUND(((F7*4.578)+194.44)+(0.92*F7*4.578),2) -> 1407.43
A8: ='DASE DADOS - DISTANCIA'!A8 -> 30064 | B8: ='DASE DADOS - DISTANCIA'!B8 -> ADELAR GEBAUER | C8: ='DASE DADOS - DISTANCIA'!C8 -> A2 | D8: ='DASE DADOS - DISTANCIA'!E8 -> CAPANEMA | E8: ='DASE DADOS - DISTANCIA'!I8 -> PLUSVAL | F8: 130 | G8: ='DASE DADOS - DISTANCIA'!J8 -> 260 | H8: 420 | I8: =IF(#REF!<17200,DISTÂNCIA3[[#This Row],[KM PARA PAGAMENTO DOS FRETES]]*4.74,((#REF!/17200)*4.74)*DISTÂNCIA3[[#This Row],[KM PARA PAGAMENTO DOS FRETES]]) -> #REF! | J8: =DISTÂNCIA3[[#This Row],[Valor CTE]]/DISTÂNCIA3[[#This Row],[KM PARA PAGAMENTO DOS FRETES]] -> 5.1427308 | K8: =ROUND((F8*4.578)+194.44,2) -> 789.58 | L8: =0.92*DISTÂNCIA3[[#This Row],[KM distancia]]*4.578 -> 547.5288 | M8: =ROUND(((F8*4.578)+194.44)+(0.92*F8*4.578),2) -> 1337.11
A9: ='DASE DADOS - DISTANCIA'!A9 -> 30668 | B9: ='DASE DADOS - DISTANCIA'!B9 -> IARA MARIA SIGNOR LAZAROTO | C9: ='DASE DADOS - DISTANCIA'!C9 -> A1 | D9: ='DASE DADOS - DISTANCIA'!E9 -> SANTO ANTÔNIO DO SUDOESTE | E9: ='DASE DADOS - DISTANCIA'!I9 -> PLUSVAL | F9: 168 | G9: ='DASE DADOS - DISTANCIA'!J9 -> 336 | H9: 420 | I9: =IF(#REF!<17200,DISTÂNCIA3[[#This Row],[KM PARA PAGAMENTO DOS FRETES]]*4.74,((#REF!/17200)*4.74)*DISTÂNCIA3[[#This Row],[KM PARA PAGAMENTO DOS FRETES]]) -> #REF! | J9: =DISTÂNCIA3[[#This Row],[Valor CTE]]/DISTÂNCIA3[[#This Row],[KM PARA PAGAMENTO DOS FRETES]] -> 4.9735714 | K9: =ROUND((F9*4.578)+194.44,2) -> 963.54 | L9: =0.92*DISTÂNCIA3[[#This Row],[KM distancia]]*4.578 -> 707.57568 | M9: =ROUND(((F9*4.578)+194.44)+(0.92*F9*4.578),2) -> 1671.12
A10: ='DASE DADOS - DISTANCIA'!A10 -> 30064 | B10: ='DASE DADOS - DISTANCIA'!B10 -> ADELAR GEBAUER | C10: ='DASE DADOS - DISTANCIA'!C10 -> A1 | D10: ='DASE DADOS - DISTANCIA'!E10 -> CAPANEMA | E10: ='DASE DADOS - DISTANCIA'!I10 -> PLUSVAL | F10: 130 | G10: ='DASE DADOS - DISTANCIA'!J10 -> 260 | H10: 420 | I10: =IF(#REF!<17200,DISTÂNCIA3[[#This Row],[KM PARA PAGAMENTO DOS FRETES]]*4.74,((#REF!/17200)*4.74)*DISTÂNCIA3[[#This Row],[KM PARA PAGAMENTO DOS FRETES]]) -> #REF! | J10: =DISTÂNCIA3[[#This Row],[Valor CTE]]/DISTÂNCIA3[[#This Row],[KM PARA PAGAMENTO DOS FRETES]] -> 5.1427308 | K10: =ROUND((F10*4.578)+194.44,2) -> 789.58 | L10: =0.92*DISTÂNCIA3[[#This Row],[KM distancia]]*4.578 -> 547.5288 | M10: =ROUND(((F10*4.578)+194.44)+(0.92*F10*4.578),2) -> 1337.11
A11: ='DASE DADOS - DISTANCIA'!A11 -> 30668 | B11: ='DASE DADOS - DISTANCIA'!B11 -> IARA MARIA SIGNOR LAZAROTO | C11: ='DASE DADOS - DISTANCIA'!C11 -> A2 | D11: ='DASE DADOS - DISTANCIA'!E11 -> SANTO ANTÔNIO DO SUDOESTE | E11: ='DASE DADOS - DISTANCIA'!I11 -> PLUSVAL | F11: 168 | G11: ='DASE DADOS - DISTANCIA'!J11 -> 336 | H11: 420 | I11: =IF(#REF!<17200,DISTÂNCIA3[[#This Row],[KM PARA PAGAMENTO DOS FRETES]]*4.74,((#REF!/17200)*4.74)*DISTÂNCIA3[[#This Row],[KM PARA PAGAMENTO DOS FRETES]]) -> #REF! | J11: =DISTÂNCIA3[[#This Row],[Valor CTE]]/DISTÂNCIA3[[#This Row],[KM PARA PAGAMENTO DOS FRETES]] -> 4.9735714 | K11: =ROUND((F11*4.578)+194.44,2) -> 963.54 | L11: =0.92*DISTÂNCIA3[[#This Row],[KM distancia]]*4.578 -> 707.57568 | M11: =ROUND(((F11*4.578)+194.44)+(0.92*F11*4.578),2) -> 1671.12
A12: ='DASE DADOS - DISTANCIA'!A12 -> 5760739 | B12: ='DASE DADOS - DISTANCIA'!B12 -> ADELAR LUIZ STURMER | C12: ='DASE DADOS - DISTANCIA'!C12 -> A1 | D12: ='DASE DADOS - DISTANCIA'!E12 -> CASCAVEL | E12: ='DASE DADOS - DISTANCIA'!I12 -> PLUMA | F12: 34 | G12: ='DASE DADOS - DISTANCIA'!J12 -> 68 | H12: 420 | I12: =IF(#REF!<17200,DISTÂNCIA3[[#This Row],[KM PARA PAGAMENTO DOS FRETES]]*4.74,((#REF!/17200)*4.74)*DISTÂNCIA3[[#This Row],[KM PARA PAGAMENTO DOS FRETES]]) -> #REF! | J12: =DISTÂNCIA3[[#This Row],[Valor CTE]]/DISTÂNCIA3[[#This Row],[KM PARA PAGAMENTO DOS FRETES]] -> 7.2542647 | K12: =ROUND((F12*4.578)+194.44,2) -> 350.09 | L12: =0.92*DISTÂNCIA3[[#This Row],[KM distancia]]*4.578 -> 143.19984 | M12: =ROUND(((F12*4.578)+194.44)+(0.92*F12*4.578),2) -> 493.29
A13: ='DASE DADOS - DISTANCIA'!A13 -> 30668 | B13: ='DASE DADOS - DISTANCIA'!B13 -> IARA MARIA SIGNOR LAZAROTO | C13: ='DASE DADOS - DISTANCIA'!C13 -> A3 | D13: ='DASE DADOS - DISTANCIA'!E13 -> SANTO ANTÔNIO DO SUDOESTE | E13: ='DASE DADOS - DISTANCIA'!I13 -> PLUSVAL | F13: 168 | G13: ='DASE DADOS - DISTANCIA'!J13 -> 336 | H13: 420 | I13: =IF(#REF!<17200,DISTÂNCIA3[[#This Row],[KM PARA PAGAMENTO DOS FRETES]]*4.74,((#REF!/17200)*4.74)*DISTÂNCIA3[[#This Row],[KM PARA PAGAMENTO DOS FRETES]]) -> #REF! | J13: =DISTÂNCIA3[[#This Row],[Valor CTE]]/DISTÂNCIA3[[#This Row],[KM PARA PAGAMENTO DOS FRETES]] -> 4.9735714 | K13: =ROUND((F13*4.578)+194.44,2) -> 963.54 | L13: =0.92*DISTÂNCIA3[[#This Row],[KM distancia]]*4.578 -> 707.57568 | M13: =ROUND(((F13*4.578)+194.44)+(0.92*F13*4.578),2) -> 1671.12
A14: ='DASE DADOS - DISTANCIA'!A14 -> 5760739 | B14: ='DASE DADOS - DISTANCIA'!B14 -> ADELAR LUIZ STURMER | C14: ='DASE DADOS - DISTANCIA'!C14 -> A2 | D14: ='DASE DADOS - DISTANCIA'!E14 -> CASCAVEL | E14: ='DASE DADOS - DISTANCIA'!I14 -> PLUMA | F14: 34 | G14: ='DASE DADOS - DISTANCIA'!J14 -> 68 | H14: 420 | I14: =IF(#REF!<17200,DISTÂNCIA3[[#This Row],[KM PARA PAGAMENTO DOS FRETES]]*4.74,((#REF!/17200)*4.74)*DISTÂNCIA3[[#This Row],[KM PARA PAGAMENTO DOS FRETES]]) -> #REF! | J14: =DISTÂNCIA3[[#This Row],[Valor CTE]]/DISTÂNCIA3[[#This Row],[KM PARA PAGAMENTO DOS FRETES]] -> 7.2542647 | K14: =ROUND((F14*4.578)+194.44,2) -> 350.09 | L14: =0.92*DISTÂNCIA3[[#This Row],[KM distancia]]*4.578 -> 143.19984 | M14: =ROUND(((F14*4.578)+194.44)+(0.92*F14*4.578),2) -> 493.29
... A129: ='DASE DADOS - DISTANCIA'!A129 -> 30342 | B129: ='DASE DADOS - DISTANCIA'!B129 -> EVE CARLA DAL BO | C129: ='DASE DADOS - DISTANCIA'!C129 -> A4 | D129: ='DASE DADOS - DISTANCIA'!E129 -> PRANCHITA | E129: ='DASE DADOS - DISTANCIA'!I129 -> PLUSVAL | F129: 155 | G129: ='DASE DADOS - DISTANCIA'!J129 -> 310 | H129: 420 | I129: =IF(#REF!<17200,DISTÂNCIA3[[#This Row],[KM PARA PAGAMENTO DOS FRETES]]*4.74,((#REF!/17200)*4.74)*DISTÂNCIA3[[#This Row],[KM PARA PAGAMENTO DOS FRETES]]) -> #REF! | J129: =DISTÂNCIA3[[#This Row],[Valor CTE]]/DISTÂNCIA3[[#This Row],[KM PARA PAGAMENTO DOS FRETES]] -> 5.0220968 | K129: =ROUND((F129*4.578)+194.44,2) -> 904.03 | L129: =0.92*DISTÂNCIA3[[#This Row],[KM distancia]]*4.578 -> 652.8228 | M129: =ROUND(((F129*4.578)+194.44)+(0.92*F129*4.578),2) -> 1556.85
A130: ='DASE DADOS - DISTANCIA'!A130 -> 30072 | B130: U | C130: ='DASE DADOS - DISTANCIA'!C130 -> A2 | D130: ='DASE DADOS - DISTANCIA'!E130 -> CAPANEMA | E130: ='DASE DADOS - DISTANCIA'!I130 -> PLUSVAL | F130: 130 | G130: ='DASE DADOS - DISTANCIA'!J130 -> 260 | H130: 420 | I130: =IF(#REF!<17200,DISTÂNCIA3[[#This Row],[KM PARA PAGAMENTO DOS FRETES]]*4.74,((#REF!/17200)*4.74)*DISTÂNCIA3[[#This Row],[KM PARA PAGAMENTO DOS FRETES]]) -> #REF! | J130: =DISTÂNCIA3[[#This Row],[Valor CTE]]/DISTÂNCIA3[[#This Row],[KM PARA PAGAMENTO DOS FRETES]] -> 5.1427308 | K130: =ROUND((F130*4.578)+194.44,2) -> 789.58 | L130: =0.92*DISTÂNCIA3[[#This Row],[KM distancia]]*4.578 -> 547.5288 | M130: =ROUND(((F130*4.578)+194.44)+(0.92*F130*4.578),2) -> 1337.11
A131: ='DASE DADOS - DISTANCIA'!A131 -> 30342 | B131: ='DASE DADOS - DISTANCIA'!B131 -> EVE CARLA DAL BO | C131: ='DASE DADOS - DISTANCIA'!C131 -> A3 | D131: ='DASE DADOS - DISTANCIA'!E131 -> PRANCHITA | E131: ='DASE DADOS - DISTANCIA'!I131 -> PLUSVAL | F131: 155 | G131: ='DASE DADOS - DISTANCIA'!J131 -> 310 | H131: 420 | I131: =IF(#REF!<17200,DISTÂNCIA3[[#This Row],[KM PARA PAGAMENTO DOS FRETES]]*4.74,((#REF!/17200)*4.74)*DISTÂNCIA3[[#This Row],[KM PARA PAGAMENTO DOS FRETES]]) -> #REF! | J131: =DISTÂNCIA3[[#This Row],[Valor CTE]]/DISTÂNCIA3[[#This Row],[KM PARA PAGAMENTO DOS FRETES]] -> 5.0220968 | K131: =ROUND((F131*4.578)+194.44,2) -> 904.03 | L131: =0.92*DISTÂNCIA3[[#This Row],[KM distancia]]*4.578 -> 652.8228 | M131: =ROUND(((F131*4.578)+194.44)+(0.92*F131*4.578),2) -> 1556.85
A132: ='DASE DADOS - DISTANCIA'!A132 -> 30072 | B132: ='DASE DADOS - DISTANCIA'!B132 -> ANDROW KELVIN GEBAUER | C132: ='DASE DADOS - DISTANCIA'!C132 -> A1 | D132: ='DASE DADOS - DISTANCIA'!E132 -> CAPANEMA | E132: ='DASE DADOS - DISTANCIA'!I132 -> PLUSVAL | F132: 130 | G132: ='DASE DADOS - DISTANCIA'!J132 -> 260 | H132: 420 | I132: =IF(#REF!<17200,DISTÂNCIA3[[#This Row],[KM PARA PAGAMENTO DOS FRETES]]*4.74,((#REF!/17200)*4.74)*DISTÂNCIA3[[#This Row],[KM PARA PAGAMENTO DOS FRETES]]) -> #REF! | J132: =DISTÂNCIA3[[#This Row],[Valor CTE]]/DISTÂNCIA3[[#This Row],[KM PARA PAGAMENTO DOS FRETES]] -> 5.1427308 | K132: =ROUND((F132*4.578)+194.44,2) -> 789.58 | L132: =0.92*DISTÂNCIA3[[#This Row],[KM distancia]]*4.578 -> 547.5288 | M132: =ROUND(((F132*4.578)+194.44)+(0.92*F132*4.578),2) -> 1337.11
A133: ='DASE DADOS - DISTANCIA'!A133 -> 30342 | B133: ='DASE DADOS - DISTANCIA'!B133 -> EVE CARLA DAL BO | C133: ='DASE DADOS - DISTANCIA'!C133 -> A2 | D133: ='DASE DADOS - DISTANCIA'!E133 -> PRANCHITA | E133: ='DASE DADOS - DISTANCIA'!I133 -> PLUSVAL | F133: 155 | G133: ='DASE DADOS - DISTANCIA'!J133 -> 310 | H133: 420 | I133: =IF(#REF!<17200,DISTÂNCIA3[[#This Row],[KM PARA PAGAMENTO DOS FRETES]]*4.74,((#REF!/17200)*4.74)*DISTÂNCIA3[[#This Row],[KM PARA PAGAMENTO DOS FRETES]]) -> #REF! | J133: =DISTÂNCIA3[[#This Row],[Valor CTE]]/DISTÂNCIA3[[#This Row],[KM PARA PAGAMENTO DOS FRETES]] -> 5.0220968 | K133: =ROUND((F133*4.578)+194.44,2) -> 904.03 | L133: =0.92*DISTÂNCIA3[[#This Row],[KM distancia]]*4.578 -> 652.8228 | M133: =ROUND(((F133*4.578)+194.44)+(0.92*F133*4.578),2) -> 1556.85
A134: ='DASE DADOS - DISTANCIA'!A134 -> 30342 | B134: ='DASE DADOS - DISTANCIA'!B134 -> EVE CARLA DAL BO | C134: ='DASE DADOS - DISTANCIA'!C134 -> A1 | D134: ='DASE DADOS - DISTANCIA'!E134 -> PRANCHITA | E134: ='DASE DADOS - DISTANCIA'!I134 -> PLUSVAL | F134: 155 | G134: ='DASE DADOS - DISTANCIA'!J134 -> 310 | H134: 420 | I134: =IF(#REF!<17200,DISTÂNCIA3[[#This Row],[KM PARA PAGAMENTO DOS FRETES]]*4.74,((#REF!/17200)*4.74)*DISTÂNCIA3[[#This Row],[KM PARA PAGAMENTO DOS FRETES]]) -> #REF! | J134: =DISTÂNCIA3[[#This Row],[Valor CTE]]/DISTÂNCIA3[[#This Row],[KM PARA PAGAMENTO DOS FRETES]] -> 5.0220968 | K134: =ROUND((F134*4.578)+194.44,2) -> 904.03 | L134: =0.92*DISTÂNCIA3[[#This Row],[KM distancia]]*4.578 -> 652.8228 | M134: =ROUND(((F134*4.578)+194.44)+(0.92*F134*4.578),2) -> 1556.85
A135: ='DASE DADOS - DISTANCIA'!A135 -> 5675936 | B135: ='DASE DADOS - DISTANCIA'!B135 -> ANTONIO FERNANDES DE OLIVEIRA | C135: ='DASE DADOS - DISTANCIA'!C135 -> A1 | D135: ='DASE DADOS - DISTANCIA'!E135 -> TOLEDO | E135: ='DASE DADOS - DISTANCIA'!I135 -> PLUMA | F135: 46 | G135: ='DASE DADOS - DISTANCIA'!J135 -> 92 | H135: 420 | I135: =IF(#REF!<17200,DISTÂNCIA3[[#This Row],[KM PARA PAGAMENTO DOS FRETES]]*4.74,((#REF!/17200)*4.74)*DISTÂNCIA3[[#This Row],[KM PARA PAGAMENTO DOS FRETES]]) -> #REF! | J135: =DISTÂNCIA3[[#This Row],[Valor CTE]]/DISTÂNCIA3[[#This Row],[KM PARA PAGAMENTO DOS FRETES]] -> 6.5083696 | K135: =ROUND((F135*4.578)+194.44,2) -> 405.03 | L135: =0.92*DISTÂNCIA3[[#This Row],[KM distancia]]*4.578 -> 193.74096 | M135: =ROUND(((F135*4.578)+194.44)+(0.92*F135*4.578),2) -> 598.77
A136: ='DASE DADOS - DISTANCIA'!A136 -> 30342 | B136: ='DASE DADOS - DISTANCIA'!B136 -> EVE CARLA DAL BO | C136: ='DASE DADOS - DISTANCIA'!C136 -> A5 | D136: ='DASE DADOS - DISTANCIA'!E136 -> PRANCHITA | E136: ='DASE DADOS - DISTANCIA'!I136 -> PLUSVAL | F136: 155 | G136: ='DASE DADOS - DISTANCIA'!J136 -> 310 | H136: 420 | I136: =IF(#REF!<17200,DISTÂNCIA3[[#This Row],[KM PARA PAGAMENTO DOS FRETES]]*4.74,((#REF!/17200)*4.74)*DISTÂNCIA3[[#This Row],[KM PARA PAGAMENTO DOS FRETES]]) -> #REF! | J136: =DISTÂNCIA3[[#This Row],[Valor CTE]]/DISTÂNCIA3[[#This Row],[KM PARA PAGAMENTO DOS FRETES]] -> 5.0220968 | K136: =ROUND((F136*4.578)+194.44,2) -> 904.03 | L136: =0.92*DISTÂNCIA3[[#This Row],[KM distancia]]*4.578 -> 652.8228 | M136: =ROUND(((F136*4.578)+194.44)+(0.92*F136*4.578),2) -> 1556.85
A137: ='DASE DADOS - DISTANCIA'!A137 -> 29887 | B137: ='DASE DADOS - DISTANCIA'!B137 -> ARDENICO DALL ALBA | C137: ='DASE DADOS - DISTANCIA'!C137 -> A1 | D137: ='DASE DADOS - DISTANCIA'!E137 -> CAPANEMA | E137: ='DASE DADOS - DISTANCIA'!I137 -> PLUSVAL | F137: 108.5 | G137: ='DASE DADOS - DISTANCIA'!J137 -> 217 | H137: 420 | I137: =IF(#REF!<17200,DISTÂNCIA3[[#This Row],[KM PARA PAGAMENTO DOS FRETES]]*4.74,((#REF!/17200)*4.74)*DISTÂNCIA3[[#This Row],[KM PARA PAGAMENTO DOS FRETES]]) -> #REF! | J137: =DISTÂNCIA3[[#This Row],[Valor CTE]]/DISTÂNCIA3[[#This Row],[KM PARA PAGAMENTO DOS FRETES]] -> 5.2909217 | K137: =ROUND((F137*4.578)+194.44,2) -> 691.15 | L137: =0.92*DISTÂNCIA3[[#This Row],[KM distancia]]*4.578 -> 456.97596 | M137: =ROUND(((F137*4.578)+194.44)+(0.92*F137*4.578),2) -> 1148.13
A138: ='DASE DADOS - DISTANCIA'!A138 -> 29958 | B138: ='DASE DADOS - DISTANCIA'!B138 -> LAIRSON THEISEN | C138: ='DASE DADOS - DISTANCIA'!C138 -> A1 | D138: ='DASE DADOS - DISTANCIA'!E138 -> CAPANEMA | E138: ='DASE DADOS - DISTANCIA'!I138 -> PLUSVAL | F138: 114.5 | G138: ='DASE DADOS - DISTANCIA'!J138 -> 229 | H138: 420 | I138: =IF(#REF!<17200,DISTÂNCIA3[[#This Row],[KM PARA PAGAMENTO DOS FRETES]]*4.74,((#REF!/17200)*4.74)*DISTÂNCIA3[[#This Row],[KM PARA PAGAMENTO DOS FRETES]]) -> #REF! | J138: =DISTÂNCIA3[[#This Row],[Valor CTE]]/DISTÂNCIA3[[#This Row],[KM PARA PAGAMENTO DOS FRETES]] -> 5.2439738 | K138: =ROUND((F138*4.578)+194.44,2) -> 718.62 | L138: =0.92*DISTÂNCIA3[[#This Row],[KM distancia]]*4.578 -> 482.24652 | M138: =ROUND(((F138*4.578)+194.44)+(0.92*F138*4.578),2) -> 1200.87
A139: ='DASE DADOS - DISTANCIA'!A139 -> 5475007 | B139: ='DASE DADOS - DISTANCIA'!B139 -> ARNO SCHMIDT | C139: ='DASE DADOS - DISTANCIA'!C139 -> A1 | D139: ='DASE DADOS - DISTANCIA'!E139 -> TOLEDO | E139: ='DASE DADOS - DISTANCIA'!I139 -> PLUMA | F139: 67 | G139: ='DASE DADOS - DISTANCIA'!J139 -> 134 | H139: 420 | I139: =IF(#REF!<17200,DISTÂNCIA3[[#This Row],[KM PARA PAGAMENTO DOS FRETES]]*4.74,((#REF!/17200)*4.74)*DISTÂNCIA3[[#This Row],[KM PARA PAGAMENTO DOS FRETES]]) -> #REF! | J139: =DISTÂNCIA3[[#This Row],[Valor CTE]]/DISTÂNCIA3[[#This Row],[KM PARA PAGAMENTO DOS FRETES]] -> 5.8458955 | K139: =ROUND((F139*4.578)+194.44,2) -> 501.17 | L139: =0.92*DISTÂNCIA3[[#This Row],[KM distancia]]*4.578 -> 282.18792 | M139: =ROUND(((F139*4.578)+194.44)+(0.92*F139*4.578),2) -> 783.35
A140: ='DASE DADOS - DISTANCIA'!A140 -> 29958 | B140: ='DASE DADOS - DISTANCIA'!B140 -> LAIRSON THEISEN | C140: ='DASE DADOS - DISTANCIA'!C140 -> A2 | D140: ='DASE DADOS - DISTANCIA'!E140 -> CAPANEMA | E140: ='DASE DADOS - DISTANCIA'!I140 -> PLUSVAL | F140: 114.5 | G140: ='DASE DADOS - DISTANCIA'!J140 -> 229 | H140: 420 | I140: =IF(#REF!<17200,DISTÂNCIA3[[#This Row],[KM PARA PAGAMENTO DOS FRETES]]*4.74,((#REF!/17200)*4.74)*DISTÂNCIA3[[#This Row],[KM PARA PAGAMENTO DOS FRETES]]) -> #REF! | J140: =DISTÂNCIA3[[#This Row],[Valor CTE]]/DISTÂNCIA3[[#This Row],[KM PARA PAGAMENTO DOS FRETES]] -> 5.2439738 | K140: =ROUND((F140*4.578)+194.44,2) -> 718.62 | L140: =0.92*DISTÂNCIA3[[#This Row],[KM distancia]]*4.578 -> 482.24652 | M140: =ROUND(((F140*4.578)+194.44)+(0.92*F140*4.578),2) -> 1200.87
A141: ='DASE DADOS - DISTANCIA'!A141 -> 5475007 | B141: ='DASE DADOS - DISTANCIA'!B141 -> ARNO SCHMIDT | C141: ='DASE DADOS - DISTANCIA'!C141 -> A2 | D141: ='DASE DADOS - DISTANCIA'!E141 -> TOLEDO | E141: ='DASE DADOS - DISTANCIA'!I141 -> PLUMA | F141: 67 | G141: ='DASE DADOS - DISTANCIA'!J141 -> 134 | H141: 420 | I141: =IF(#REF!<17200,DISTÂNCIA3[[#This Row],[KM PARA PAGAMENTO DOS FRETES]]*4.74,((#REF!/17200)*4.74)*DISTÂNCIA3[[#This Row],[KM PARA PAGAMENTO DOS FRETES]]) -> #REF! | J141: =DISTÂNCIA3[[#This Row],[Valor CTE]]/DISTÂNCIA3[[#This Row],[KM PARA PAGAMENTO DOS FRETES]] -> 5.8458955 | K141: =ROUND((F141*4.578)+194.44,2) -> 501.17 | L141: =0.92*DISTÂNCIA3[[#This Row],[KM distancia]]*4.578 -> 282.18792 | M141: =ROUND(((F141*4.578)+194.44)+(0.92*F141*4.578),2) -> 783.35
A142: ='DASE DADOS - DISTANCIA'!A142 -> 30465 | B142: ='DASE DADOS - DISTANCIA'!B142 -> LIANE EBERT | C142: ='DASE DADOS - DISTANCIA'!C142 -> A1 | D142: ='DASE DADOS - DISTANCIA'!E142 -> CAPANEMA | E142: ='DASE DADOS - DISTANCIA'!I142 -> PLUSVAL | F142: 129.5 | G142: ='DASE DADOS - DISTANCIA'!J142 -> 259 | H142: 420 | I142: =IF(#REF!<17200,DISTÂNCIA3[[#This Row],[KM PARA PAGAMENTO DOS FRETES]]*4.74,((#REF!/17200)*4.74)*DISTÂNCIA3[[#This Row],[KM PARA PAGAMENTO DOS FRETES]]) -> #REF! | J142: =DISTÂNCIA3[[#This Row],[Valor CTE]]/DISTÂNCIA3[[#This Row],[KM PARA PAGAMENTO DOS FRETES]] -> 5.1455985 | K142: =ROUND((F142*4.578)+194.44,2) -> 787.29 | L142: =0.92*DISTÂNCIA3[[#This Row],[KM distancia]]*4.578 -> 545.42292 | M142: =ROUND(((F142*4.578)+194.44)+(0.92*F142*4.578),2) -> 1332.71
... A207: ='DASE DADOS - DISTANCIA'!A207 -> 30664 | B207: ='DASE DADOS - DISTANCIA'!B207 -> EDEVIR CONTI | C207: ='DASE DADOS - DISTANCIA'!C207 -> A1 | D207: ='DASE DADOS - DISTANCIA'!E207 -> PRANCHITA | E207: ='DASE DADOS - DISTANCIA'!I207 -> PLUSVAL | F207: 156.5 | G207: ='DASE DADOS - DISTANCIA'!J207 -> 313 | H207: 420 | I207: =IF(#REF!<17200,DISTÂNCIA3[[#This Row],[KM PARA PAGAMENTO DOS FRETES]]*4.74,((#REF!/17200)*4.74)*DISTÂNCIA3[[#This Row],[KM PARA PAGAMENTO DOS FRETES]]) -> #REF! | J207: =DISTÂNCIA3[[#This Row],[Valor CTE]]/DISTÂNCIA3[[#This Row],[KM PARA PAGAMENTO DOS FRETES]] -> 5.0161022 | K207: =ROUND((F207*4.578)+194.44,2) -> 910.9 | L207: =0.92*DISTÂNCIA3[[#This Row],[KM distancia]]*4.578 -> 659.14044 | M207: =ROUND(((F207*4.578)+194.44)+(0.92*F207*4.578),2) -> 1570.04
A208: ='DASE DADOS - DISTANCIA'!A208 -> 41901 | B208: ='DASE DADOS - DISTANCIA'!B208 -> LUCAS EDUARDO LUFT | C208: ='DASE DADOS - DISTANCIA'!C208 -> A2 | D208: ='DASE DADOS - DISTANCIA'!E208 -> CAPANEMA | E208: ='DASE DADOS - DISTANCIA'!I208 -> PLUSVAL | F208: 120 | G208: 240 | H208: 420 | I208: =IF(#REF!<17200,DISTÂNCIA3[[#This Row],[KM PARA PAGAMENTO DOS FRETES]]*4.74,((#REF!/17200)*4.74)*DISTÂNCIA3[[#This Row],[KM PARA PAGAMENTO DOS FRETES]]) -> #REF! | J208: =DISTÂNCIA3[[#This Row],[Valor CTE]]/DISTÂNCIA3[[#This Row],[KM PARA PAGAMENTO DOS FRETES]] -> 5.2050417 | K208: =ROUND((F208*4.578)+194.44,2) -> 743.8 | L208: =0.92*DISTÂNCIA3[[#This Row],[KM distancia]]*4.578 -> 505.4112 | M208: =ROUND(((F208*4.578)+194.44)+(0.92*F208*4.578),2) -> 1249.21
A209: ='DASE DADOS - DISTANCIA'!A209 -> 30058 | B209: ='DASE DADOS - DISTANCIA'!B209 -> ELIMAR SCHINDLER | C209: ='DASE DADOS - DISTANCIA'!C209 -> A1 | D209: ='DASE DADOS - DISTANCIA'!E209 -> CAPANEMA | E209: ='DASE DADOS - DISTANCIA'!I209 -> PLUSVAL | F209: 121.5 | G209: ='DASE DADOS - DISTANCIA'!J209 -> 243 | H209: 420 | I209: =IF(#REF!<17200,DISTÂNCIA3[[#This Row],[KM PARA PAGAMENTO DOS FRETES]]*4.74,((#REF!/17200)*4.74)*DISTÂNCIA3[[#This Row],[KM PARA PAGAMENTO DOS FRETES]]) -> #REF! | J209: =DISTÂNCIA3[[#This Row],[Valor CTE]]/DISTÂNCIA3[[#This Row],[KM PARA PAGAMENTO DOS FRETES]] -> 5.1950617 | K209: =ROUND((F209*4.578)+194.44,2) -> 750.67 | L209: =0.92*DISTÂNCIA3[[#This Row],[KM distancia]]*4.578 -> 511.72884 | M209: =ROUND(((F209*4.578)+194.44)+(0.92*F209*4.578),2) -> 1262.4
A210: ='DASE DADOS - DISTANCIA'!A210 -> 41901 | B210: ='DASE DADOS - DISTANCIA'!B210 -> LUCAS EDUARDO LUFT | C210: ='DASE DADOS - DISTANCIA'!C210 -> A1 | D210: ='DASE DADOS - DISTANCIA'!E210 -> CAPANEMA | E210: ='DASE DADOS - DISTANCIA'!I210 -> PLUSVAL | F210: 120 | G210: ='DASE DADOS - DISTANCIA'!J210 -> 240 | H210: 420 | I210: =IF(#REF!<17200,DISTÂNCIA3[[#This Row],[KM PARA PAGAMENTO DOS FRETES]]*4.74,((#REF!/17200)*4.74)*DISTÂNCIA3[[#This Row],[KM PARA PAGAMENTO DOS FRETES]]) -> #REF! | J210: =DISTÂNCIA3[[#This Row],[Valor CTE]]/DISTÂNCIA3[[#This Row],[KM PARA PAGAMENTO DOS FRETES]] -> 5.2050417 | K210: =ROUND((F210*4.578)+194.44,2) -> 743.8 | L210: =0.92*DISTÂNCIA3[[#This Row],[KM distancia]]*4.578 -> 505.4112 | M210: =ROUND(((F210*4.578)+194.44)+(0.92*F210*4.578),2) -> 1249.21
A211: ='DASE DADOS - DISTANCIA'!A211 -> 29954 | B211: ='DASE DADOS - DISTANCIA'!B211 -> ELIMARI MAROSTIKA ROSO | C211: ='DASE DADOS - DISTANCIA'!C211 -> A1 | D211: ='DASE DADOS - DISTANCIA'!E211 -> CAPANEMA | E211: ='DASE DADOS - DISTANCIA'!I211 -> PLUSVAL | F211: 121.5 | G211: ='DASE DADOS - DISTANCIA'!J211 -> 243 | H211: 420 | I211: =IF(#REF!<17200,DISTÂNCIA3[[#This Row],[KM PARA PAGAMENTO DOS FRETES]]*4.74,((#REF!/17200)*4.74)*DISTÂNCIA3[[#This Row],[KM PARA PAGAMENTO DOS FRETES]]) -> #REF! | J211: =DISTÂNCIA3[[#This Row],[Valor CTE]]/DISTÂNCIA3[[#This Row],[KM PARA PAGAMENTO DOS FRETES]] -> 5.1950617 | K211: =ROUND((F211*4.578)+194.44,2) -> 750.67 | L211: =0.92*DISTÂNCIA3[[#This Row],[KM distancia]]*4.578 -> 511.72884 | M211: =ROUND(((F211*4.578)+194.44)+(0.92*F211*4.578),2) -> 1262.4
A212: ='DASE DADOS - DISTANCIA'!A212 -> 29432 | B212: ='DASE DADOS - DISTANCIA'!B212 -> DELIRDES DAL PIVA KIPPER | C212: ='DASE DADOS - DISTANCIA'!C212 -> A1 | D212: ='DASE DADOS - DISTANCIA'!E212 -> CAPANEMA | E212: ='DASE DADOS - DISTANCIA'!I212 -> PLUSVAL | F212: 124.5 | G212: ='DASE DADOS - DISTANCIA'!J212 -> 249 | H212: 420 | I212: =IF(#REF!<17200,DISTÂNCIA3[[#This Row],[KM PARA PAGAMENTO DOS FRETES]]*4.74,((#REF!/17200)*4.74)*DISTÂNCIA3[[#This Row],[KM PARA PAGAMENTO DOS FRETES]]) -> #REF! | J212: =DISTÂNCIA3[[#This Row],[Valor CTE]]/DISTÂNCIA3[[#This Row],[KM PARA PAGAMENTO DOS FRETES]] -> 5.1757831 | K212: =ROUND((F212*4.578)+194.44,2) -> 764.4 | L212: =0.92*DISTÂNCIA3[[#This Row],[KM distancia]]*4.578 -> 524.36412 | M212: =ROUND(((F212*4.578)+194.44)+(0.92*F212*4.578),2) -> 1288.77
A213: ='DASE DADOS - DISTANCIA'!A213 -> 29423 | B213: ='DASE DADOS - DISTANCIA'!B213 -> ELIO MINSKI | C213: ='DASE DADOS - DISTANCIA'!C213 -> A1 | D213: ='DASE DADOS - DISTANCIA'!E213 -> CAPANEMA | E213: ='DASE DADOS - DISTANCIA'!I213 -> PLUSVAL | F213: 114.5 | G213: ='DASE DADOS - DISTANCIA'!J213 -> 229 | H213: 420 | I213: =IF(#REF!<17200,DISTÂNCIA3[[#This Row],[KM PARA PAGAMENTO DOS FRETES]]*4.74,((#REF!/17200)*4.74)*DISTÂNCIA3[[#This Row],[KM PARA PAGAMENTO DOS FRETES]]) -> #REF! | J213: =DISTÂNCIA3[[#This Row],[Valor CTE]]/DISTÂNCIA3[[#This Row],[KM PARA PAGAMENTO DOS FRETES]] -> 5.2439738 | K213: =ROUND((F213*4.578)+194.44,2) -> 718.62 | L213: =0.92*DISTÂNCIA3[[#This Row],[KM distancia]]*4.578 -> 482.24652 | M213: =ROUND(((F213*4.578)+194.44)+(0.92*F213*4.578),2) -> 1200.87
A214: ='DASE DADOS - DISTANCIA'!A214 -> 29950 | B214: ='DASE DADOS - DISTANCIA'!B214 -> DELMIR LUIZ TRARBACH | C214: ='DASE DADOS - DISTANCIA'!C214 -> A2 | D214: ='DASE DADOS - DISTANCIA'!E214 -> CAPANEMA | E214: ='DASE DADOS - DISTANCIA'!I214 -> PLUSVAL | F214: 116 | G214: ='DASE DADOS - DISTANCIA'!J214 -> 232 | H214: 420 | I214: =IF(#REF!<17200,DISTÂNCIA3[[#This Row],[KM PARA PAGAMENTO DOS FRETES]]*4.74,((#REF!/17200)*4.74)*DISTÂNCIA3[[#This Row],[KM PARA PAGAMENTO DOS FRETES]]) -> #REF! | J214: =DISTÂNCIA3[[#This Row],[Valor CTE]]/DISTÂNCIA3[[#This Row],[KM PARA PAGAMENTO DOS FRETES]] -> 5.2329741 | K214: =ROUND((F214*4.578)+194.44,2) -> 725.49 | L214: =0.92*DISTÂNCIA3[[#This Row],[KM distancia]]*4.578 -> 488.56416 | M214: =ROUND(((F214*4.578)+194.44)+(0.92*F214*4.578),2) -> 1214.05
A215: ='DASE DADOS - DISTANCIA'!A215 -> 29423 | B215: ='DASE DADOS - DISTANCIA'!B215 -> ELIO MINSKI | C215: ='DASE DADOS - DISTANCIA'!C215 -> A2 | D215: ='DASE DADOS - DISTANCIA'!E215 -> CAPANEMA | E215: ='DASE DADOS - DISTANCIA'!I215 -> PLUSVAL | F215: 114.5 | G215: ='DASE DADOS - DISTANCIA'!J215 -> 229 | H215: 420 | I215: =IF(#REF!<17200,DISTÂNCIA3[[#This Row],[KM PARA PAGAMENTO DOS FRETES]]*4.74,((#REF!/17200)*4.74)*DISTÂNCIA3[[#This Row],[KM PARA PAGAMENTO DOS FRETES]]) -> #REF! | J215: =DISTÂNCIA3[[#This Row],[Valor CTE]]/DISTÂNCIA3[[#This Row],[KM PARA PAGAMENTO DOS FRETES]] -> 5.2439738 | K215: =ROUND((F215*4.578)+194.44,2) -> 718.62 | L215: =0.92*DISTÂNCIA3[[#This Row],[KM distancia]]*4.578 -> 482.24652 | M215: =ROUND(((F215*4.578)+194.44)+(0.92*F215*4.578),2) -> 1200.87
A216: ='DASE DADOS - DISTANCIA'!A216 -> 29950 | B216: ='DASE DADOS - DISTANCIA'!B216 -> DELMIR LUIZ TRARBACH | C216: ='DASE DADOS - DISTANCIA'!C216 -> A1 | D216: ='DASE DADOS - DISTANCIA'!E216 -> CAPANEMA | E216: ='DASE DADOS - DISTANCIA'!I216 -> PLUSVAL | F216: 116 | G216: ='DASE DADOS - DISTANCIA'!J216 -> 232 | H216: 420 | I216: =IF(#REF!<17200,DISTÂNCIA3[[#This Row],[KM PARA PAGAMENTO DOS FRETES]]*4.74,((#REF!/17200)*4.74)*DISTÂNCIA3[[#This Row],[KM PARA PAGAMENTO DOS FRETES]]) -> #REF! | J216: =DISTÂNCIA3[[#This Row],[Valor CTE]]/DISTÂNCIA3[[#This Row],[KM PARA PAGAMENTO DOS FRETES]] -> 5.2329741 | K216: =ROUND((F216*4.578)+194.44,2) -> 725.49 | L216: =0.92*DISTÂNCIA3[[#This Row],[KM distancia]]*4.578 -> 488.56416 | M216: =ROUND(((F216*4.578)+194.44)+(0.92*F216*4.578),2) -> 1214.05
A217: ='DASE DADOS - DISTANCIA'!A217 -> 835528 | B217: ='DASE DADOS - DISTANCIA'!B217 -> GEFERSON MOSSULIN | C217: ='DASE DADOS - DISTANCIA'!C217 -> A1 | D217: ='DASE DADOS - DISTANCIA'!E217 -> CAPITÃO LEÔNIDAS MARQUES | E217: ='DASE DADOS - DISTANCIA'!I217 -> PLUSVAL | F217: 70 | G217: ='DASE DADOS - DISTANCIA'!J217 -> 140 | H217: 420 | I217: =IF(#REF!<17200,DISTÂNCIA3[[#This Row],[KM PARA PAGAMENTO DOS FRETES]]*4.74,((#REF!/17200)*4.74)*DISTÂNCIA3[[#This Row],[KM PARA PAGAMENTO DOS FRETES]]) -> #REF! | J217: =DISTÂNCIA3[[#This Row],[Valor CTE]]/DISTÂNCIA3[[#This Row],[KM PARA PAGAMENTO DOS FRETES]] -> 5.7837143 | K217: =ROUND((F217*4.578)+194.44,2) -> 514.9 | L217: =0.92*DISTÂNCIA3[[#This Row],[KM distancia]]*4.578 -> 294.8232 | M217: =ROUND(((F217*4.578)+194.44)+(0.92*F217*4.578),2) -> 809.72
A218: ='DASE DADOS - DISTANCIA'!A218 -> 984442 | B218: ='DASE DADOS - DISTANCIA'!B218 -> GILBERTO PAGLIARINI | C218: ='DASE DADOS - DISTANCIA'!C218 -> A1 | D218: ='DASE DADOS - DISTANCIA'!E218 -> PRANCHITA | E218: ='DASE DADOS - DISTANCIA'!I218 -> PLUSVAL | F218: 139.5 | G218: ='DASE DADOS - DISTANCIA'!J218 -> 279 | H218: 420 | I218: =IF(#REF!<17200,DISTÂNCIA3[[#This Row],[KM PARA PAGAMENTO DOS FRETES]]*4.74,((#REF!/17200)*4.74)*DISTÂNCIA3[[#This Row],[KM PARA PAGAMENTO DOS FRETES]]) -> #REF! | J218: =DISTÂNCIA3[[#This Row],[Valor CTE]]/DISTÂNCIA3[[#This Row],[KM PARA PAGAMENTO DOS FRETES]] -> 5.0917921 | K218: =ROUND((F218*4.578)+194.44,2) -> 833.07 | L218: =0.92*DISTÂNCIA3[[#This Row],[KM distancia]]*4.578 -> 587.54052 | M218: =ROUND(((F218*4.578)+194.44)+(0.92*F218*4.578),2) -> 1420.61
...
